2024-03-24 15:42:20,043 INFO    StreamThr :4139276 [internal.py:wandb_internal():86] W&B internal server running at pid: 4139276, started at: 2024-03-24 15:42:20.041929
2024-03-24 15:42:20,045 DEBUG   HandlerThread:4139276 [handler.py:handle_request():146] handle_request: status
2024-03-24 15:42:20,053 INFO    WriterThread:4139276 [datastore.py:open_for_write():85] open: /mnt/nas2/home/wangshaobo/data/Transformer_learning/wandb/run-20240324_154220-wxv2k2x9/run-wxv2k2x9.wandb
2024-03-24 15:42:20,054 DEBUG   SenderThread:4139276 [sender.py:send():382] send: header
2024-03-24 15:42:20,074 DEBUG   SenderThread:4139276 [sender.py:send():382] send: run
2024-03-24 15:42:20,732 ERROR   SenderThread:4139276 [internal_api.py:execute():373] 404 response executing GraphQL.
2024-03-24 15:42:20,732 ERROR   SenderThread:4139276 [internal_api.py:execute():374] {"errors":[{"message":"project not found","path":["upsertBucket"]}],"data":{"upsertBucket":null}}
2024-03-24 15:42:20,732 ERROR   SenderThread:4139276 [sender.py:send_run():987] It appears that you do not have permission to access the requested resource. Please reach out to the project owner to grant you access. If you have the correct permissions, verify that there are no issues with your networking setup.(Error 404: Not Found)
Traceback (most recent call last):
  File "/home/wangshaobo/anaconda3/envs/faithseg/lib/python3.9/site-packages/wandb/sdk/lib/retry.py", line 131, in __call__
    result = self._call_fn(*args, **kwargs)
  File "/home/wangshaobo/anaconda3/envs/faithseg/lib/python3.9/site-packages/wandb/sdk/internal/internal_api.py", line 369, in execute
    return self.client.execute(*args, **kwargs)  # type: ignore
  File "/home/wangshaobo/anaconda3/envs/faithseg/lib/python3.9/site-packages/wandb/vendor/gql-0.2.0/wandb_gql/client.py", line 52, in execute
    result = self._get_result(document, *args, **kwargs)
  File "/home/wangshaobo/anaconda3/envs/faithseg/lib/python3.9/site-packages/wandb/vendor/gql-0.2.0/wandb_gql/client.py", line 60, in _get_result
    return self.transport.execute(document, *args, **kwargs)
  File "/home/wangshaobo/anaconda3/envs/faithseg/lib/python3.9/site-packages/wandb/sdk/lib/gql_request.py", line 59, in execute
    request.raise_for_status()
  File "/home/wangshaobo/anaconda3/envs/faithseg/lib/python3.9/site-packages/requests/models.py", line 1021, in raise_for_status
    raise HTTPError(http_error_msg, response=self)
requests.exceptions.HTTPError: 404 Client Error: Not Found for url: https://api.wandb.ai/graphql

During handling of the above exception, another exception occurred:

Traceback (most recent call last):
  File "/home/wangshaobo/anaconda3/envs/faithseg/lib/python3.9/site-packages/wandb/sdk/internal/sender.py", line 985, in send_run
    self._init_run(run, config_value_dict)
  File "/home/wangshaobo/anaconda3/envs/faithseg/lib/python3.9/site-packages/wandb/sdk/internal/sender.py", line 1027, in _init_run
    server_run, inserted, server_messages = self._api.upsert_run(
  File "/home/wangshaobo/anaconda3/envs/faithseg/lib/python3.9/site-packages/wandb/apis/normalize.py", line 73, in wrapper
    raise err
  File "/home/wangshaobo/anaconda3/envs/faithseg/lib/python3.9/site-packages/wandb/apis/normalize.py", line 41, in wrapper
    return func(*args, **kwargs)
  File "/home/wangshaobo/anaconda3/envs/faithseg/lib/python3.9/site-packages/wandb/sdk/internal/internal_api.py", line 2212, in upsert_run
    response = self.gql(
  File "/home/wangshaobo/anaconda3/envs/faithseg/lib/python3.9/site-packages/wandb/sdk/internal/internal_api.py", line 341, in gql
    ret = self._retry_gql(
  File "/home/wangshaobo/anaconda3/envs/faithseg/lib/python3.9/site-packages/wandb/sdk/lib/retry.py", line 147, in __call__
    retry_timedelta_triggered = check_retry_fn(e)
  File "/home/wangshaobo/anaconda3/envs/faithseg/lib/python3.9/site-packages/wandb/util.py", line 965, in check_retry_fn
    return fallback_retry_fn(e)
  File "/home/wangshaobo/anaconda3/envs/faithseg/lib/python3.9/site-packages/wandb/util.py", line 907, in no_retry_auth
    raise CommError(
wandb.errors.CommError: It appears that you do not have permission to access the requested resource. Please reach out to the project owner to grant you access. If you have the correct permissions, verify that there are no issues with your networking setup.(Error 404: Not Found)
2024-03-24 15:42:22,809 DEBUG   HandlerThread:4139276 [handler.py:handle_request():146] handle_request: shutdown
2024-03-24 15:42:22,809 INFO    HandlerThread:4139276 [handler.py:finish():866] shutting down handler
2024-03-24 15:42:23,074 INFO    WriterThread:4139276 [datastore.py:close():294] close: /mnt/nas2/home/wangshaobo/data/Transformer_learning/wandb/run-20240324_154220-wxv2k2x9/run-wxv2k2x9.wandb
2024-03-24 15:42:23,794 INFO    SenderThread:4139276 [sender.py:finish():1548] shutting down sender
